[2023-10-25 20:00:50,279] {taskinstance.py:896} INFO - Dependencies all met for <TaskInstance: booking_ingestion.load_data 2023-10-24T20:00:00.625617+00:00 [queued]>
[2023-10-25 20:00:50,368] {taskinstance.py:896} INFO - Dependencies all met for <TaskInstance: booking_ingestion.load_data 2023-10-24T20:00:00.625617+00:00 [queued]>
[2023-10-25 20:00:50,373] {taskinstance.py:1087} INFO - 
--------------------------------------------------------------------------------
[2023-10-25 20:00:50,375] {taskinstance.py:1088} INFO - Starting attempt 1 of 1
[2023-10-25 20:00:50,377] {taskinstance.py:1089} INFO - 
--------------------------------------------------------------------------------
[2023-10-25 20:00:50,575] {taskinstance.py:1107} INFO - Executing <Task(PythonOperator): load_data> on 2023-10-24T20:00:00.625617+00:00
[2023-10-25 20:00:50,586] {standard_task_runner.py:52} INFO - Started process 112 to run task
[2023-10-25 20:00:50,602] {standard_task_runner.py:76} INFO - Running: ['airflow', 'tasks', 'run', 'booking_ingestion', 'load_data', '2023-10-24T20:00:00.625617+00:00', '--job-id', '3', '--pool', 'default_pool', '--raw', '--subdir', 'DAGS_FOLDER/main.py', '--cfg-path', '/tmp/tmpd86zi73o', '--error-file', '/tmp/tmp6i6c2hii']
[2023-10-25 20:00:50,605] {standard_task_runner.py:77} INFO - Job 3: Subtask load_data
[2023-10-25 20:00:50,787] {logging_mixin.py:104} INFO - Running <TaskInstance: booking_ingestion.load_data 2023-10-24T20:00:00.625617+00:00 [running]> on host ccb9baf257e2
[2023-10-25 20:00:51,055] {taskinstance.py:1300} INFO - Exporting the following env vars:
AIRFLOW_CTX_DAG_OWNER=airflow
AIRFLOW_CTX_DAG_ID=booking_ingestion
AIRFLOW_CTX_TASK_ID=load_data
AIRFLOW_CTX_EXECUTION_DATE=2023-10-24T20:00:00.625617+00:00
AIRFLOW_CTX_DAG_RUN_ID=scheduled__2023-10-24T20:00:00.625617+00:00
[2023-10-25 20:00:51,060] {taskinstance.py:1501} ERROR - Task failed with exception
Traceback (most recent call last):
  File "/home/airflow/.local/lib/python3.8/site-packages/airflow/models/taskinstance.py", line 1157, in _run_raw_task
    self._prepare_and_execute_task_with_callbacks(context, task)
  File "/home/airflow/.local/lib/python3.8/site-packages/airflow/models/taskinstance.py", line 1331, in _prepare_and_execute_task_with_callbacks
    result = self._execute_task(context, task_copy)
  File "/home/airflow/.local/lib/python3.8/site-packages/airflow/models/taskinstance.py", line 1361, in _execute_task
    result = task_copy.execute(context=context)
  File "/home/airflow/.local/lib/python3.8/site-packages/airflow/operators/python.py", line 150, in execute
    return_value = self.execute_callable()
  File "/home/airflow/.local/lib/python3.8/site-packages/airflow/operators/python.py", line 161, in execute_callable
    return self.python_callable(*self.op_args, **self.op_kwargs)
  File "/opt/airflow/dags/main.py", line 34, in load_data
    conn = sqlite3.connect("/Users/mike/airflow/airflow-docker/db/datascience.db")
sqlite3.OperationalError: unable to open database file
[2023-10-25 20:00:51,082] {taskinstance.py:1544} INFO - Marking task as FAILED. dag_id=booking_ingestion, task_id=load_data, execution_date=20231024T200000, start_date=20231025T200050, end_date=20231025T200051
[2023-10-25 20:00:51,318] {local_task_job.py:151} INFO - Task exited with return code 1
