[2023-10-25 19:45:20,024] {taskinstance.py:896} INFO - Dependencies all met for <TaskInstance: booking_ingestion.load_data 2023-10-24T19:44:19.812154+00:00 [queued]>
[2023-10-25 19:45:20,083] {taskinstance.py:896} INFO - Dependencies all met for <TaskInstance: booking_ingestion.load_data 2023-10-24T19:44:19.812154+00:00 [queued]>
[2023-10-25 19:45:20,087] {taskinstance.py:1087} INFO - 
--------------------------------------------------------------------------------
[2023-10-25 19:45:20,089] {taskinstance.py:1088} INFO - Starting attempt 1 of 1
[2023-10-25 19:45:20,090] {taskinstance.py:1089} INFO - 
--------------------------------------------------------------------------------
[2023-10-25 19:45:20,301] {taskinstance.py:1107} INFO - Executing <Task(PythonOperator): load_data> on 2023-10-24T19:44:19.812154+00:00
[2023-10-25 19:45:20,313] {standard_task_runner.py:52} INFO - Started process 42 to run task
[2023-10-25 19:45:20,339] {standard_task_runner.py:76} INFO - Running: ['airflow', 'tasks', 'run', 'booking_ingestion', 'load_data', '2023-10-24T19:44:19.812154+00:00', '--job-id', '3', '--pool', 'default_pool', '--raw', '--subdir', 'DAGS_FOLDER/main.py', '--cfg-path', '/tmp/tmpcaroxedh', '--error-file', '/tmp/tmp0dobi8q1']
[2023-10-25 19:45:20,343] {standard_task_runner.py:77} INFO - Job 3: Subtask load_data
[2023-10-25 19:45:20,771] {logging_mixin.py:104} INFO - Running <TaskInstance: booking_ingestion.load_data 2023-10-24T19:44:19.812154+00:00 [running]> on host ccb9baf257e2
[2023-10-25 19:45:21,209] {taskinstance.py:1300} INFO - Exporting the following env vars:
AIRFLOW_CTX_DAG_OWNER=airflow
AIRFLOW_CTX_DAG_ID=booking_ingestion
AIRFLOW_CTX_TASK_ID=load_data
AIRFLOW_CTX_EXECUTION_DATE=2023-10-24T19:44:19.812154+00:00
AIRFLOW_CTX_DAG_RUN_ID=scheduled__2023-10-24T19:44:19.812154+00:00
[2023-10-25 19:45:21,216] {taskinstance.py:1501} ERROR - Task failed with exception
Traceback (most recent call last):
  File "/home/airflow/.local/lib/python3.8/site-packages/airflow/models/taskinstance.py", line 1157, in _run_raw_task
    self._prepare_and_execute_task_with_callbacks(context, task)
  File "/home/airflow/.local/lib/python3.8/site-packages/airflow/models/taskinstance.py", line 1331, in _prepare_and_execute_task_with_callbacks
    result = self._execute_task(context, task_copy)
  File "/home/airflow/.local/lib/python3.8/site-packages/airflow/models/taskinstance.py", line 1361, in _execute_task
    result = task_copy.execute(context=context)
  File "/home/airflow/.local/lib/python3.8/site-packages/airflow/operators/python.py", line 150, in execute
    return_value = self.execute_callable()
  File "/home/airflow/.local/lib/python3.8/site-packages/airflow/operators/python.py", line 161, in execute_callable
    return self.python_callable(*self.op_args, **self.op_kwargs)
  File "/opt/airflow/dags/main.py", line 34, in load_data
    conn = sqlite3.connect("usr/local/airflow/db/datascience.db")
sqlite3.OperationalError: unable to open database file
[2023-10-25 19:45:21,232] {taskinstance.py:1544} INFO - Marking task as FAILED. dag_id=booking_ingestion, task_id=load_data, execution_date=20231024T194419, start_date=20231025T194520, end_date=20231025T194521
[2023-10-25 19:45:21,507] {local_task_job.py:151} INFO - Task exited with return code 1
